Workbook

Sheet trb
A1: E & G Repacking
A2: Magcamiguing, Calamba, Misamis Occidental
A4: Trial Balance
A5: As of December 31,2020
A7: Account Name | B7: Previous | D7: Current
B8: DR | C8: CR | D8: DR | F8: CR
A10: Cash /Check | E10: =400054-26272.13+100000 -> 473781.87
A11: Materials Inventory | E11: =324523.08+30253 -> 354776.08 | R11: =+M15-N22-#REF!+#REF!+M35 -> #REF!
A12: Finished Goods Inventory | E12: ='Asset-C'!C234 -> 0 | S12: =+N19+N26-M32 -> 0
A13: Merchandise Inventory | R13: =+M21-#REF!-N36 -> #REF!
A14: Accounts Receivable | E14: =188623.8+25000+60000 -> 273623.8 | R14: =+M28 -> 0
A15: Land and Building | R15: =+M18+M25-#REF!-N16+M31-N33 -> #REF!
A16: Transportation Equipment | E16: 480000 | R16: =SUM(R11:R15) -> #REF! | S16: =SUM(S11:S15) -> 0
A17: Office Equipment | E17: 56000 | R17: =+R16-S16 -> #REF!
A18: Accum. Depreciation - TE | F18: =168258.77+16253.3 -> 184512.07
A19: Accum. Depreciation - OE | F19: =33525.22+5223.2 -> 38748.42
A20: Accum. Depreciation - Bldg
A21: Accounts Payable | F21: 0
A22: Loans Payable - Short Term | F22: =328223.2-81741.6+15359.75 -> 261841.35
A23: Loans Payable - Long Term | F23: 0
A24: Accrued Expense | F24: ='Payables-C'!F56 -> 8232.58
A25: EG, Capital | F25: 500000
A26: EG, Withdrawal | E26: 325885
A27: Retained Earnings | F27: 525103.38
A28: Sales | F28: =1652436+253+160000 -> 1812689 | G28: =+F28-E31 -> 1112430.8
A29: Sales Returns & Allowances | E29: ='Income & Expense-C'!C49 -> 0
A30: Sales Discount | E30: ='Income & Expense-C'!C62 -> 0
A31: COS | E31: 700258.25 | G31: =+F28-E31 -> 1112430.8 | H31: =+F28-G31 -> 700258.25
A32: Salaries and Wages | E32: 160258 | H32: =+F28-H31 -> 1112430.8
A33: Sales Commission | E33: 96000 | H33: =+H32-G42 -> 445628.95
A34: Board, Lodging and Meals | E34: 0
A35: Depreciation Exp - TE | E35: 16253.3
A36: Depreciation Exp - OE | E36: 5223.2
A37: Depreciation Exp - Bldg | E37: 0
A38: Fuel and Lubricants | E38: 180118
A39: Repair and Maintenace | E39: 45625.3
A40: Interest Expense
A41: Power, Light and Water | E41: 90000
A42: Postage,Telephone and Cable Exp. | E42: 15000 | G42: =+E32+E33+E38+E39+E41+E42+E43+E35+E36 -> 666801.8
A43: Taxes and Licenses | E43: 58324
...

Sheet bs
A1: E & G Repacking
A2: Magcamiguing, Calamba. Misamis Occidental
A4: Balance Sheet
A5: =trb!A5 -> As of December 31,2020
C7: Previous | F7: Current | I7: Inc./Dec.
A8: Assets
A9: Current Assets:
B10: =trb!A10 -> Cash /Check | C10: =trb!B10 -> 0 | F10: =trb!E10 -> 473781.87 | I10: =+C10-F10 -> -473781.87
B11: =trb!A11 -> Materials Inventory | C11: =trb!B11 -> 0 | F11: =trb!E11 -> 354776.08 | I11: =+C11-F11 -> -354776.08
B12: =trb!A12 -> Finished Goods Inventory | C12: =trb!B12 -> 0 | F12: =trb!E12 -> 0 | I12: =+C12-F12 -> 0
B13: =trb!A13 -> Merchandise Inventory | C13: =trb!B13 -> 0 | F13: =trb!E13 -> 0 | I13: =+C13-F13 -> 0
B14: =trb!A14 -> Accounts Receivable | C14: =trb!B14 -> 0 | E14: =SUM(C10:C14) -> 0 | F14: =trb!E14 -> 273623.8 | H14: =SUM(F10:F14) -> 1102181.8 | I14: =+C14-F14 -> -273623.8
A16: Fixed Assets:
B17: =trb!A15 -> Land and Building | C17: =trb!B15 -> 0 | F17: =trb!E15 -> 0
B18: =trb!A20 -> Accum. Depreciation - Bldg | F18: =-trb!F20 -> 0
B19: =trb!A16 -> Transportation Equipment | C19: =trb!B16 -> 0 | F19: =trb!E16 -> 480000 | I19: =+F19-C19 -> 480000
B20: =trb!A18 -> Accum. Depreciation - TE | C20: =-trb!C18 -> 0 | F20: =-trb!F18 -> -184512.07 | I20: =+F20-C20 -> -184512.07
B21: =trb!A17 -> Office Equipment | C21: =trb!B17 -> 0 | F21: =trb!E17 -> 56000 | I21: =+F21-C21 -> 56000
B22: =trb!A19 -> Accum. Depreciation - OE | C22: =-trb!C19 -> 0 | E22: =SUM(C17:C22) -> 0 | F22: =-trb!F19 -> -38748.42 | H22: =SUM(F17:G22) -> 312739.51 | I22: =+F22-C22 -> -38748.42
A24: Total Assets | E24: =SUM(E10:E22) -> 0 | H24: =SUM(H10:H22) -> 1414921.3 | I24: =SUM(I10:I22) -> -789442.24
A27: Liabilities and Equity
A29: Current Liabilities:
B30: =trb!A21 -> Accounts Payable | C30: =trb!C21 -> 0 | F30: =trb!F21 -> 0 | I30: =+F30-C30 -> 0
B31: =trb!A22 -> Loans Payable - Short Term | C31: =trb!C22 -> 0 | F31: =trb!F22 -> 261841.35
B32: =trb!A24 -> Accrued Expense | C32: =trb!C23 -> 0 | F32: =trb!F24 -> 8232.58 | H32: =SUM(F30:F32) -> 270073.93 | I32: =+F32-C32 -> 8232.58
A34: Long-term Liabilities:
B35: =trb!A23 -> Loans Payable - Long Term | C35: =trb!C23 -> 0 | E35: =SUM(C35:D35) -> 0 | F35: =trb!F23 -> 0 | H35: =SUM(F35:G35) -> 0 | I35: =+F35-C35 -> 0
A37: Owner's Equity
B38: =trb!A25 -> EG, Capital | C38: =trb!C25 -> 0 | F38: =+trb!F25 -> 500000 | I38: =+F38-C38 -> 500000
B39: =trb!A26 -> EG, Withdrawal | C39: =-trb!B26 -> 0 | F39: =-trb!E26 -> -325885 | I39: =+F39-C39 -> -325885
B40: Retained Earnings, Beg | C40: =trb!C27 -> 0 | F40: =trb!F27 -> 525103.38
B41: Retained Earnings, Current | C41: =IS!F37 -> #REF! | E41: =SUM(C38:C41) -> #REF! | F41: =IS!I37 -> 445628.95 | H41: =SUM(F38:F41) -> 1144847.3 | I41: =+F41-C41 -> #REF!
A43: Total Liabilities and Owner's Equity | E43: =SUM(E30:E41) -> #REF! | H43: =SUM(H30:H41) -> 1414921.3 | I43: =SUM(I30:I41) -> #REF!
E44: =E24-E43 -> #REF! | H44: =H24-H43 -> 0 | I44: =I24-I43 -> #REF!
B47: Certified Correct by:
B49: ELMER A. CARTAGENAS
B50: Proprietor

Sheet IS
A1: E & G Repacking
A2: Magcamiguing, Calamba, Misamis Occidental
A4: Income Statement
B5: For the month ended December 31,2020
D7: Previous | G7: To Date | J7: Previous Month | M7: This Month
B8: Revenue from Sales:
B9: Sales (net of Sales Discounts) | F9: =trb!C28 -> 0 | I9: =trb!F28 -> 1812689 | L9: 9130208.1 | O9: =+I9-L9 -> -7317519.1
B10: Less: | C10: Sales returns & allowances | D10: =trb!B30 -> 0 | G10: =trb!E29 -> 0 | J10: 0 | M10: =+G10-J10 -> 0
C11: Sales Discounts | D11: =trb!B29 -> 0 | F11: =+D10+D11 -> 0 | G11: =trb!E30 -> 0 | I11: =+G10+G11 -> 0 | J11: 0 | L11: 0 | M11: =+G11-J11 -> 0 | O11: =+M10+M11 -> 0
B12: Net sales | F12: =+F9-F11 -> 0 | I12: =+I9-I11 -> 1812689 | L12: =L9 -> 9130208.1 | O12: =+O9-O11 -> -7317519.1
B14: Less: | C14: Cost of Goods Sold
C16: Inventory, Beginning | G16: 324523.08 | J16: 2263775 | M16: =+G16-J16 -> -1939251.9
C17: Add: Purchases & Freight-in | D17: =#REF! -> #REF! | G17: =712582.25+17929 -> 730511.25 | J17: 4233470.8 | M17: =+G17-J17 -> -3502959.5
C18: Cost of Goods Available for Sale | D18: =SUM(D16:D17) -> #REF! | G18: =G16+G17 -> 1055034.3 | J18: =SUM(J16:J17) -> 6497245.7 | M18: =SUM(M16:M17) -> -5442211.4
C19: Less: Inventory, Ending | D19: =trb!#REF! -> #REF! | F19: =+D18-D19 -> #REF! | G19: =trb!E11 -> 354776.08 | I19: =+G18-G19 -> 700258.25 | J19: 1035581.3 | L19: =+J18-J19 -> 5461664.5 | M19: =+G19-J19 -> -680805.21 | O19: =+M18-M19 -> -4761406.2
B22: Gross Profit | F22: =+F12-F19-#REF! -> #REF! | I22: =+I12-I19 -> 1112430.8 | L22: =+L12-L19 -> 3668543.7 | O22: =+O12-O19 -> -2556112.9
B23: Less: | C23: Operating Expenses
C25: =[1]trb!A32 -> Salaries and Wages | D25: =[1]trb!B32 -> 0 | G25: =trb!E32 -> 160258 | J25: 295435 | M25: =+G25-J25 -> -135177
C26: =[1]trb!A33 -> Sales Commission | G26: =trb!E33 -> 96000 | J26: 135810.6 | M26: =+G26-J26 -> -39810.6
C27: Depreciation Exp - TE | G27: =trb!E35 -> 16253.3
C28: Depreciation Exp - OE | G28: =trb!E36 -> 5223.2
C29: =[1]trb!A38 -> Fuel and Lubricants | D29: =[1]trb!B39 -> 0 | G29: =trb!E38 -> 180118 | J29: 262975.67 | M29: =+G29-J29 -> -82857.67
C30: =[1]trb!A41 -> Power, Light and Water | D30: =[1]trb!B41 -> 0 | G30: =trb!E41 -> 90000 | J30: 162070.27 | M30: =+G30-J30 -> -72070.27
C31: =[1]trb!A42 -> Postage,Telephone and Cable Exp. | D31: =[1]trb!B42 -> 0 | G31: =trb!E42 -> 15000 | J31: 204230.56 | M31: =+G31-J31 -> -189230.56
C32: Taxes and Licenses | D32: =trb!B41 -> 0 | G32: =trb!E43 -> 58324 | J32: 78484.5 | M32: =+G32-J32 -> -20160.5
C33: Repair and Maintenance | G33: =trb!E39 -> 45625.3 | J33: 56037.01 | M33: =+G33-J33 -> -10411.71
J34: 2600 | M34: =+G34-J34 -> -2600
I35: =SUM(G25:G35) -> 666801.8 | J35: 2000 | L35: =SUM(J25:J35) -> 1199643.6 | M35: =+G35-J35 -> -2000 | O35: =SUM(M25:M35) -> -554318.31
B37: Net Income/(Loss) | F37: =+F22-F35 -> #REF! | I37: =+I22-I35 -> 445628.95 | L37: =+L22-L35 -> 2468900.1 | O37: =+O22-O35 -> -2001794.6
B40: Prepared by:
C42: Bookkeeper
B45: Noted by:
C47: Owner/Manager
C55: Certified Correct by:
C58: ELMER A. CARTAGENAS
C59: Proprietor

Sheet -

Sheet Asset-C
A1: Current
A3: Cash | H3: =[2]trb!$A$11 -> Materials Inventory
A5: Beg. Balance | C5: 3353769.7 | D5: 42422 | E5: 1 | F5: 45430.5 | H5: Beg. Balance | J5: 2254978.4 | K5: 42559 | L5: 52 | M5: 528841.18
A6: 42559 | B6: 52 | C6: 1143792.9 | D6: - | E6: 2 | F6: 6631.5 | H6: 42422 | I6: 1 | J6: 45430.5 | K6: - | L6: 53 | M6: 423517.43
A7: - | B7: 53 | C7: 864724.5 | D7: - | E7: 3 | F7: 600 | H7: 42431 | I7: 5 | J7: 20200 | K7: - | L7: 54 | M7: 867336.05
A8: - | B8: 54 | C8: 1712278.6 | D8: - | E8: 4 | F8: 1290 | H8: - | I8: 6 | J8: 52480 | K8: 42715 | L8: 100 | M8: 418213.99
A9: 42715 | B9: 100 | C9: 917340.65 | D9: 42431 | E9: 5 | F9: 20200 | H9: - | I9: 7 | J9: 56530 | K9: - | L9: 101 | M9: 352788.27
A10: - | B10: 101 | C10: 729393.95 | D10: - | E10: 6 | F10: 52480 | H10: 42433 | I10: 11 | J10: 63940 | K10: 42735 | L10: 104 | M10: 57885.63
A11: 42735 | B11: 104 | C11: 117524.1 | D11: - | E11: 7 | F11: 56530 | H11: 42473 | I11: 19 | J11: 62515 | L11: 105 | M11: 50904.7
A12: - | B12: 105 | C12: 91687.65 | D12: - | E12: 8 | F12: 47489.4 | H12: - | I12: 21 | J12: 65820 | L12: 108 | M12: 781418.82
A13: - | B13: 108 | C13: 1599809.7 | D13: - | E13: 9 | F13: 5056.79 | H13: - | I13: 22 | J13: 64331.8
D14: 42433 | E14: 10 | F14: 54096 | H14: - | I14: 23 | J14: 74500
D15: - | E15: 11 | F15: 63940 | H15: - | I15: 24 | J15: 110
D16: - | E16: 12 | F16: 300 | H16: 42489 | I16: 27 | J16: 27943.08
D17: - | E17: 13 | F17: 1290 | H17: 42528 | I17: 31 | J17: 61700
D18: - | E18: 14 | F18: 500 | H18: - | I18: 35 | J18: 128330
D19: 42473 | E19: 15 | F19: 300 | H19: 42538 | I19: 36 | J19: 102100
D20: - | E20: 16 | F20: 30102 | H20: - | I20: 37 | J20: 76110
D21: - | E21: 17 | F21: 132280 | H21: 42566 | I21: 43 | J21: 34000
D22: - | E22: 18 | F22: 1290 | H22: - | I22: 45 | J22: 65820
D23: - | E23: 19 | F23: 62515 | H23: 42578 | I23: 55 | J23: 123880
D24: - | E24: 20 | F24: 54096 | H24: - | I24: 56 | J24: 132500
D25: - | E25: 21 | F25: 65820 | H25: - | I25: 58 | J25: 65820
D26: - | E26: 22 | F26: 64331.8 | H26: 42601 | I26: 66 | J26: 42500
D27: - | E27: 23 | F27: 74500 | H27: 42608 | I27: 67 | J27: 17000
D28: - | E28: 24 | F28: 110 | H28: 42608 | I28: 68 | J28: 45610
D29: 42489 | E29: 25 | F29: 1290 | H29: 42646 | I29: 76 | J29: 60450
D30: - | E30: 26 | F30: 1850 | H30: - | I30: 77 | J30: 110550
D31: - | E31: 27 | F31: 27943.08 | H31: 42713 | I31: 95 | J31: 60200
D32: 42505 | E32: 29 | F32: 129205.31 | H32: - | I32: 96 | J32: 61425
D33: 42528 | E33: 30 | F33: 1290 | H33: 42735 | I33: 114 | J33: 167520
D34: - | E34: 31 | F34: 61700 | H34: - | I34: 116 | J34: 167698
D35: - | E35: 32 | F35: 300 | H35: - | I35: 117 | J35: 103841.5
D36: - | E36: 33 | F36: 66811.2
D37: - | E37: 34 | F37: 10920
D38: - | E38: 35 | F38: 128330
D39: 42538 | E39: 36 | F39: 102100
D40: - | E40: 37 | F40: 76110
D41: 42552 | E41: 38 | F41: 9325.6
D42: - | E42: 39 | F42: 300
...

Sheet Payables-C
A1: Current
A3: =[2]trb!$A$21 -> Accounts Payable
D5: Beg. Balance | F5: 89700
C14: =SUM(C5:C13) -> 0 | F14: =SUM(F5:F13) -> 89700
F17: =+F14-C14 -> 89700
A21: =[2]trb!$A$22 -> Loans Payable - Short Term
A23: 42505 | C23: 111887.93 | D23: Beg. Balance | F23: 942594.78
A24: 42589 | C24: 50000.01
A25: 42735 | C25: 58880.52
C35: =SUM(C23:C34) -> 220768.46 | F35: =SUM(F23:F34) -> 942594.78
F38: =+F35-C35 -> 721826.32
A43: Accrued Expense
D45: Beg. Balance | F45: 8232.58
C53: =SUM(C45:C52) -> 0 | F53: =SUM(F45:F52) -> 8232.58
F56: =+F53-C53 -> 8232.58

Sheet Income & Expense-C
A1: Current
A3: =[2]trb!$A$27 -> Sales
D5: Beg. Balance | F5: 0
D6: 42559 | E6: 52 | F6: 1143792.9
D7: - | E7: 53 | F7: 864724.5
D8: - | E8: 54 | F8: 1712278.6
D9: 42715 | E9: 100 | F9: 917340.65
D10: - | E10: 101 | F10: 729393.95
D11: 42735 | E11: 104 | F11: 117524.1
D12: - | E12: 105 | F12: 91687.65
D13: - | E13: 108 | F13: 1599809.7
C28: =SUM(C5:C27) -> 0 | F28: =SUM(F5:F27) -> 7176552
F31: =+F28-C28 -> 7176552
A36: =[2]trb!$A$28 -> Sales Returns & Allowances
A38: Beg. Balance | C38: 0
C46: =SUM(C38:C45) -> 0 | F46: =SUM(F38:F45) -> 0
C49: =+C46-F46 -> 0
A53: =[2]trb!$A$29 -> Sales Discount
A55: Beg. Balance | C55: 0
C59: =SUM(C55:C58) -> 0 | F59: =SUM(F55:F58) -> 0
C62: =+C59-F59 -> 0
A66: =trb!A31 -> COS
A68: Beg. Balance | C68: 0
A69: 42559 | B69: 52 | C69: 625311.38
A70: - | B70: 53 | C70: 505736.8
A71: - | B71: 54 | C71: 898588.85
A72: 42715 | B72: 100 | C72: 481174.99
A73: - | B73: 101 | C73: 411752.94
A74: 42735 | B74: 104 | C74: 63702.43
A75: - | B75: 105 | C75: 53011.2
A76: - | B76: 108 | C76: 836048.82
C90: =SUM(C68:C89) -> 3875327.4 | F90: =SUM(F68:F89) -> 0
C93: =+C90-F90 -> 3875327.4
A97: =trb!A32 -> Salaries and Wages | H97: =[2]trb!$A$32 -> Sales Commission
A99: Beg. Balance | C99: 0 | H99: Beg. Balance | J99: 0
A100: 42735 | B100: 106 | C100: 90000 | H100: 42735 | I100: 106 | J100: 88971.04
A101: - | B101: 107 | C101: 86000 | H101: - | I101: 107 | J101: 67950.19
C118: =SUM(C99:C117) -> 176000 | F118: =SUM(F99:F117) -> 0 | J118: =SUM(J99:J117) -> 156921.23 | M118: =SUM(M99:M117) -> 0
C121: =+C118-F118 -> 176000 | J121: =+J118-M118 -> 156921.23
A125: =trb!A34 -> Board, Lodging and Meals | H125: =[2]trb!$A$34 -> Depreciation Exp - TE
...

Sheet Equity-C
A1: Current
A3: =[2]trb!$A$24 -> EG, Capital
F5: 1200000
C15: =SUM(C5:C14) -> 0 | F15: =SUM(F5:F14) -> 1200000
F18: =+F15-C15 -> 1200000
A22: =[2]trb!$A$25 -> EG, Withdrawal
C24: 740779.17
A25: 41729 | B25: #45 | C25: 219000
A26: 41786 | B26: #82 | C26: 1838
A27: 41946 | B27: #191 | C27: 1135.35
A28: 41959 | B28: #195 | C28: 1240
A29: 41967 | B29: #197 | C29: 1100
A30: 42735 | B30: 109 | C30: 245160
C34: =SUM(C24:C33) -> 1210252.5 | F34: =SUM(F24:F33) -> 0
C37: =+C34-F34 -> 1210252.5
A41: =[2]trb!$A$26 -> Retained Earnings
D43: Beg | F43: =2860744.48105226+744862.42 -> 3605606.9
D44: 12/2014 | F44: 1978547.5
D45: 12/2015 | F45: 2090948.9
C53: =SUM(C43:C52) -> 0 | F53: =SUM(F43:F52) -> 7675103.3
F56: =+F53-C53 -> 7675103.3

Sheet Sheet1
F6: sales | G6: cos-mat | H6: cos-mdse
F7: =292999.1+17860 -> 310859.1 | G7: 133012.03 | H7: 15600 | I7: =+F7-G7-H7 -> 162247.07
F8: 177936 | G8: 99044.34 | I8: =+F8-G8-H8 -> 78891.66
F9: 288321.6 | G9: 148982.8 | I9: =+F9-G9-H9 -> 139338.8
F10: =211613.6+71.4 -> 211685 | G10: 113627.56 | H10: 52.8 | I10: =+F10-G10-H10 -> 98004.64
F11: 305031.2 | G11: 175966.37 | I11: =+F11-G11-H11 -> 129064.83
F12: =400585.7+17860 -> 418445.7 | G12: 196702.95 | H12: 15600 | I12: =+F12-G12-H12 -> 206142.75
I13: =+F13-G13-H13 -> 0
I14: =+F14-G14-H14 -> 0
I15: =+F15-G15-H15 -> 0
I16: =+F16-G16-H16 -> 0
I17: =+F17-G17-H17 -> 0
I18: =+F18-G18-H18 -> 0
I19: =+F19-G19-H19 -> 0
I20: =+F20-G20-H20 -> 0
I21: =+F21-G21-H21 -> 0
I22: =+F22-G22-H22 -> 0
I23: =+F23-G23-H23 -> 0
I24: =+F24-G24-H24 -> 0
... I33: =+F33-G33-H33 -> 0
F36: =SUM(F7:F35) -> 1712278.6 | G36: =SUM(G7:G35) -> 867336.05 | H36: =SUM(H7:H35) -> 31252.8 | I36: =SUM(I7:I35) -> 813689.75
G38: =+G36+H36 -> 898588.85
